const n = 9;

try {
  n = 2;
} catch (err) {
  console.log(`E: ${err}`);
}
